Workbook

Sheet Master data
D1: Support coverage | F1: ROI
B2: High | C2: 3 | D2: 3 | F2: >24 | G2: 1
B3: Medium | C3: 2 | D3: 2 | F3: >12 <=24 | G3: 2
B4: Low | C4: 1 | D4: 1 | F4: <=12 | G4: 3

Sheet Agents ACN prio
C1: Current State (Readiness) | K1: Expected RoI (Value) | Q1: Go To Market Priority | S1: Score
B2: Digital Agent | C2: Standardization | D2: Standardization Score | E2: Adoption | F2: Adoption Score | G2: Data availability & Quality | H2: Data score | I2: Support Coverage | J2: Support Score | K2: Cost Avoidance | L2: Cost Score | M2: Sales & Profitability | N2: Revenue Score | O2: Time to value (Months) | P2: TtV Score
A3: Lead-to-Order | B3: Master Data Quality Agent | C3: High | D3: =IFERROR(VLOOKUP(C3,'Master data'!$B$2:$C$4,2,FALSE),0) | E3: Medium | F3: =IFERROR(VLOOKUP(E3,'Master data'!$B$2:$C$4,2,FALSE),0) | G3: High | H3: =IFERROR(VLOOKUP(G3,'Master data'!$B$2:$C$4,2,FALSE),0) | I3: Medium | J3: =IFERROR(VLOOKUP(I3,'Master data'!$B$2:$D$4,3,FALSE),0) | K3: High | L3: =IFERROR(VLOOKUP(K3,'Master data'!$B$2:$C$4,2,FALSE),0) | M3: Medium | N3: =IFERROR(VLOOKUP(M3,'Master data'!$B$2:$C$4,2,FALSE),0) | O3: <=12 | P3: =IFERROR(VLOOKUP(O3,'Master data'!$F$2:$G$4,2,FALSE),0) | R3: =IF(Q3="X",1,0) | S3: =SUM(D3,F3,H3,J3,L3,N3,P3,R3)
B4: Quote Configuration Agent | C4: Low | D4: =IFERROR(VLOOKUP(C4,'Master data'!$B$2:$C$4,2,FALSE),0) | E4: Low | F4: =IFERROR(VLOOKUP(E4,'Master data'!$B$2:$C$4,2,FALSE),0) | G4: Medium | H4: =IFERROR(VLOOKUP(G4,'Master data'!$B$2:$C$4,2,FALSE),0) | I4: Low | J4: =IFERROR(VLOOKUP(I4,'Master data'!$B$2:$D$4,3,FALSE),0) | K4: High | L4: =IFERROR(VLOOKUP(K4,'Master data'!$B$2:$C$4,2,FALSE),0) | M4: High | N4: =IFERROR(VLOOKUP(M4,'Master data'!$B$2:$C$4,2,FALSE),0) | O4: >12 <=24 | P4: =IFERROR(VLOOKUP(O4,'Master data'!$F$2:$G$4,2,FALSE),0) | R4: =IF(Q4="X",1,0) | S4: =SUM(D4,F4,H4,J4,L4,N4,P4,R4)
B5: Credit Decision Agent | C5: High | D5: =IFERROR(VLOOKUP(C5,'Master data'!$B$2:$C$4,2,FALSE),0) | E5: Medium | F5: =IFERROR(VLOOKUP(E5,'Master data'!$B$2:$C$4,2,FALSE),0) | G5: High | H5: =IFERROR(VLOOKUP(G5,'Master data'!$B$2:$C$4,2,FALSE),0) | I5: Medium | J5: =IFERROR(VLOOKUP(I5,'Master data'!$B$2:$D$4,3,FALSE),0) | K5: High | L5: =IFERROR(VLOOKUP(K5,'Master data'!$B$2:$C$4,2,FALSE),0) | M5: High | N5: =IFERROR(VLOOKUP(M5,'Master data'!$B$2:$C$4,2,FALSE),0) | O5: <=12 | P5: =IFERROR(VLOOKUP(O5,'Master data'!$F$2:$G$4,2,FALSE),0) | R5: =IF(Q5="X",1,0) | S5: =SUM(D5,F5,H5,J5,L5,N5,P5,R5)
B6: Compliance Orchestration Agent | C6: Medium | D6: =IFERROR(VLOOKUP(C6,'Master data'!$B$2:$C$4,2,FALSE),0) | E6: Medium | F6: =IFERROR(VLOOKUP(E6,'Master data'!$B$2:$C$4,2,FALSE),0) | G6: High | H6: =IFERROR(VLOOKUP(G6,'Master data'!$B$2:$C$4,2,FALSE),0) | I6: Medium | J6: =IFERROR(VLOOKUP(I6,'Master data'!$B$2:$D$4,3,FALSE),0) | K6: High | L6: =IFERROR(VLOOKUP(K6,'Master data'!$B$2:$C$4,2,FALSE),0) | M6: High | N6: =IFERROR(VLOOKUP(M6,'Master data'!$B$2:$C$4,2,FALSE),0) | O6: >12 <=24 | P6: =IFERROR(VLOOKUP(O6,'Master data'!$F$2:$G$4,2,FALSE),0) | R6: =IF(Q6="X",1,0) | S6: =SUM(D6,F6,H6,J6,L6,N6,P6,R6)
B7: Quote Routing & Approval Agent | C7: High | D7: =IFERROR(VLOOKUP(C7,'Master data'!$B$2:$C$4,2,FALSE),0) | E7: Medium | F7: =IFERROR(VLOOKUP(E7,'Master data'!$B$2:$C$4,2,FALSE),0) | G7: High | H7: =IFERROR(VLOOKUP(G7,'Master data'!$B$2:$C$4,2,FALSE),0) | I7: High | J7: =IFERROR(VLOOKUP(I7,'Master data'!$B$2:$D$4,3,FALSE),0) | K7: Medium | L7: =IFERROR(VLOOKUP(K7,'Master data'!$B$2:$C$4,2,FALSE),0) | M7: High | N7: =IFERROR(VLOOKUP(M7,'Master data'!$B$2:$C$4,2,FALSE),0) | O7: <=12 | P7: =IFERROR(VLOOKUP(O7,'Master data'!$F$2:$G$4,2,FALSE),0) | R7: =IF(Q7="X",1,0) | S7: =SUM(D7,F7,H7,J7,L7,N7,P7,R7)
B8: Quote Conversion Agent | C8: Medium | D8: =IFERROR(VLOOKUP(C8,'Master data'!$B$2:$C$4,2,FALSE),0) | E8: Medium | F8: =IFERROR(VLOOKUP(E8,'Master data'!$B$2:$C$4,2,FALSE),0) | G8: High | H8: =IFERROR(VLOOKUP(G8,'Master data'!$B$2:$C$4,2,FALSE),0) | I8: Medium | J8: =IFERROR(VLOOKUP(I8,'Master data'!$B$2:$D$4,3,FALSE),0) | K8: Medium | L8: =IFERROR(VLOOKUP(K8,'Master data'!$B$2:$C$4,2,FALSE),0) | M8: High | N8: =IFERROR(VLOOKUP(M8,'Master data'!$B$2:$C$4,2,FALSE),0) | O8: <=12 | P8: =IFERROR(VLOOKUP(O8,'Master data'!$F$2:$G$4,2,FALSE),0) | R8: =IF(Q8="X",1,0) | S8: =SUM(D8,F8,H8,J8,L8,N8,P8,R8)
A9: Order-to-Cash | N9: =IFERROR(VLOOKUP(M9,'Master data'!$B$2:$C$4,2,FALSE),0) | P9: =IFERROR(VLOOKUP(O9,'Master data'!$F$2:$G$4,2,FALSE),0) | Q9: X | R9: =IF(Q9="X",1,0) | S9: =SUM(D9,F9,H9,J9,L9,N9,P9,R9)
N10: =IFERROR(VLOOKUP(M10,'Master data'!$B$2:$C$4,2,FALSE),0) | P10: =IFERROR(VLOOKUP(O10,'Master data'!$F$2:$G$4,2,FALSE),0) | R10: =IF(Q10="X",1,0) | S10: =SUM(D10,F10,H10,J10,L10,N10,P10,R10)
N11: =IFERROR(VLOOKUP(M11,'Master data'!$B$2:$C$4,2,FALSE),0) | P11: =IFERROR(VLOOKUP(O11,'Master data'!$F$2:$G$4,2,FALSE),0) | R11: =IF(Q11="X",1,0) | S11: =SUM(D11,F11,H11,J11,L11,N11,P11,R11)
N12: =IFERROR(VLOOKUP(M12,'Master data'!$B$2:$C$4,2,FALSE),0) | P12: =IFERROR(VLOOKUP(O12,'Master data'!$F$2:$G$4,2,FALSE),0) | R12: =IF(Q12="X",1,0) | S12: =SUM(D12,F12,H12,J12,L12,N12,P12,R12)
D13: =IFERROR(VLOOKUP(C13,'Master data'!$B$2:$C$4,2,FALSE),0) | R13: =IF(Q13="X",1,0)
D14: =IFERROR(VLOOKUP(C14,'Master data'!$B$2:$C$4,2,FALSE),0) | R14: =IF(Q14="X",1,0)
D15: =IFERROR(VLOOKUP(C15,'Master data'!$B$2:$C$4,2,FALSE),0) | R15: =IF(Q15="X",1,0)
D16: =IFERROR(VLOOKUP(C16,'Master data'!$B$2:$C$4,2,FALSE),0) | R16: =IF(Q16="X",1,0)
D17: =IFERROR(VLOOKUP(C17,'Master data'!$B$2:$C$4,2,FALSE),0) | R17: =IF(Q17="X",1,0)
D18: =IFERROR(VLOOKUP(C18,'Master data'!$B$2:$C$4,2,FALSE),0) | R18: =IF(Q18="X",1,0)
D19: =IFERROR(VLOOKUP(C19,'Master data'!$B$2:$C$4,2,FALSE),0) | R19: =IF(Q19="X",1,0)
D20: =IFERROR(VLOOKUP(C20,'Master data'!$B$2:$C$4,2,FALSE),0) | R20: =IF(Q20="X",1,0)
D21: =IFERROR(VLOOKUP(C21,'Master data'!$B$2:$C$4,2,FALSE),0) | R21: =IF(Q21="X",1,0)
D22: =IFERROR(VLOOKUP(C22,'Master data'!$B$2:$C$4,2,FALSE),0) | R22: =IF(Q22="X",1,0)
D23: =IFERROR(VLOOKUP(C23,'Master data'!$B$2:$C$4,2,FALSE),0) | R23: =IF(Q23="X",1,0)
D24: =IFERROR(VLOOKUP(C24,'Master data'!$B$2:$C$4,2,FALSE),0) | R24: =IF(Q24="X",1,0)
... D51: =IFERROR(VLOOKUP(C51,'Master data'!$B$2:$C$4,2,FALSE),0) | R51: =IF(Q51="X",1,0)

Sheet ACN Agentfactory
A2: # | B2: ACCOUNT | C2: Flag (ignore) | D2: REGION | E2: INDUSTRY | F2: USE CASES (including Agent Name) | G2: Project POC (Ent ID) | H2: Project Status (Pipeline, In Progress, Completed) | I2: Production Status (In Production, In development, On Hold) | J2: Reasoning for Production / No Production | K2: Roadmap Created? (Yes/No) | L2: Funding Type (Salesforce Funded, Accenture Funded, Client Funded) | M2: Owner
D3: (AMERICA/EMEA/APAC/Innovation/Others)
A4: 1 | B4: Illumina | D4: AMERICA | E4: Life Science | F4: Knowledge Grounded Emails, | H4: Completed | I4: In Production | J4: Market Demand | K4: No | L4: Client funded | M4: Sitansu
F5: Case Summaries, and generate email with integrated order data from salesforce
A6: 2 | B6: Boston Scientific | D6: AMERICA | E6: Life Science | F6: Knowledge Grounded Emails, Account Summaries, and voice to action while logging a call in salesforce | H6: Completed | I6: In Production | J6: Market Demand | K6: No | L6: Client funded | M6: Sitansu
A7: 3 | B7: Stryker 1.0 | D7: AMERICA | E7: Life Science | F7: Duplicate case retrieval and case update.Identfying missing information in a case and showing it in the agent conversation.Data cloud reports/Dashboard for monitoring credits getting consumed in each session , as well as user based consumtion.Updatring the agentic conversation in the custom rich text field in Salesforce.Drafting an email with the summary so that it can be sent to the user. | H7: Completed | I7: In Production
A8: 4 | B8: Stryker 2.0 | D8: AMERICA | E8: Life Science | F8: Implemented the requirement of Stryker 1.0 with Employee Agent.Also Created few more reports Data cloud reports for the Agent Credits consumption with respect to specific employee agent. | H8: Completed | I8: In Production
A9: 5 | B9: CES SF POC | D9: AMERICA | E9: Telecom | F9: Enhanced Agentforce capabilities by integrating it with the Google CES agent using the Agent API.Leveraged Data cloud Data library to store the knowledge articles which can be used by the agent to suggest trouble shooting steps before actually suggesting an upgraded Internet plan. | H9: Completed | I9: In Production
A10: 6 | B10: Marriott | D10: AMERICA | E10: PRD | F10: Created a Employee Agent default for Marriott internal service rep. This use case was built to reduce the manual efforts of service representatives to search the latest facts of Marriott Properties hosted on 3rd party app. Agent will search the exact answer to the query and summarize it rather than searching up the whole hotel fact sheet. Agent will also be able to handle queries from knowledge it will summarize the related articles using RAG search. | H10: Completed | I10: In Production | K10: No | L10: Client funded | M10: Neetu
A11: 7 | B11: Salesforce | D11: AMERICA | E11: CMT | F11: Created a custom employee agent for Account Success team.This Employee Agent will assist for more than 2,600 CSM users/managers to assist with creating, updating, and closing Engagements. This CSM agent also offers extra capabilities like summarizing the Success Path, calculating sentiment scores, Search web & Slack and handling team assignments. Furthermore, Accenture created a Sales Coach for the Success Overview custom object.​ | H11: In Progress | I11: In Production | K11: No | L11: Client funded | M11: Neetu
A12: 8 | B12: Proactive Adoption Agent​ ​ | D12: AMERICA | E12: Technology | F12: An AI-powered agent assesses customer adoption of specific features and provides personalized guidance to enhance usage. If adoption is low, it educates users on feature value, onboarding, and best practices while checking understanding and sharing relevant resources. For premier and signature customers, the agent facilitates Guide Engagements or expert-led coaching sessions to drive deeper adoption.​ | H12: In Progress | I12: In Development
A13: 9 | B13: McKesson | D13: AMERICA | E13: Healthcare | F13: An AI-powered agent autonomously identify missing information from a customer email and auto-generate a targeted and concise response to collect missing information, | H13: Completed | I13: In Production | J13: Market Demand | K13: No | L13: Clinet Funded | M13: Sitansu
F14: Recommend knowledge articles to support the customer request and use selected article in response generation,
F15: Generate a case summary with customer sentiment
F16: Take in additional thread context from the case beyond incoming email (started)
A17: 10 | B17: Net Zero Cloud | D17: AMERICA | E17: Sustainibility | F17: The FY25 Supplier Portal roadmap uses Generative AI and deep data integration to modernize procurement—shifting from manual reviews to automated, insight-driven decision-making. | H17: Completed | I17: In Production
F18: Core capabilities and value:
F19: GenAI Supplier Assessment: Automatically analyzes supplier surveys to assess decarbonization readiness, delivering faster, actionable insights.
F20: AI ESG Scoring: Applies a consistent, configurable AI framework to score and benchmark supplier sustainability performance.
F21: Supplier Profile Dashboard: Provides a centralized, visual view of ESG ratings, risks, trends, and action items for greater transparency.
F22: ESG Compass (for Suppliers): Enables peer benchmarking and guidance to help suppliers identify gaps and improve ESG performance.
F23: Supplier Improvement Plans: Auto-generates tailored improvement actions to drive accountability, risk mitigation, and progress.
F24: Overall impact:
F25: Faster insights, data-driven ESG decisions, improved transparency, proactive risk management, and stronger supplier engagement on sustainability and decarbonization.
A26: 11 | B26: ACIS | D26: AMERICA | E26: Public Sector | F26: 1. Agent should automate the intake process by listening to callers and populating fields in any order. Data should be captured in a structured format. Call should be automatically transcribed as the call is going. | H26: In Progress | I26: In Development | K26: Yes | L26: Accenture Funded | M26: Ankur Omar
F27: 2. Agent should generate appropriate forms based on data received from the call.
F28: 3. Agent should coach the caseworker to ensure all required information is captured (even if out of order or incorrect). For example, if the address is not correct, the agent should prompt user to fix it (in real-time). Or prompt back if data is missing.
F29: Summarize of case
F30: 4. Agent should recommends services/programs proven effective for similar demographic profiles
A31: 12 | B31: Virtual Sales Agent | E31: Auto Cloud
A32: 13 | B32: Proactive Service Agent | E32: Auto Cloud
A33: 14 | B33: B2B Sales | D33: AMERICA | E33: Sales Cloud | F33: Key Themes & Use Cases for B2B Sales: | G33: manoj.b.kumar.mishra | H33: In Progress | I33: In Production | J33: Market Demand | K33: Yes | L33: Accenture Funded | M33: Manoj
F34: AI-Driven Sales Productivity (Employee Agent):
F36: 1. Daily task prioritization and prospecting
F37: 2. Automated opportunity and quote creation
F38: 3. Intelligent product and discount recommendations
F39: 4. End-to-end quote lifecycle management
F40: 5. Transcript summarization and follow-up scheduling
F41: Customer Retention & Insights (Employee Agent):
F42: 1. Proactive churn detection using usage and sentiment data
...

Sheet Agents Siemens criteria
A1: Super Agent Use Case | B1: Sub-Agent Use Cases | C1: Agent Description (short) | D1: Pain Point Addressed | E1: Agent Technology | F1: Agent Specification | K1: Existing ACN Assets | L1: Siemens Criteria | X1: Value x Effort
F2: Host System | G2: Input (Sources/Supplier) | H2: How does this agent technically work? | I2: Agent Output | J2: KPIs to measure business impact | L2: Business Value Potential | N2: Cross-business Applicability | P2: Technical Complexity & Feasibility | R2: Data readiness and ACP compliance | T2: Alignment with existing initiatives | V2: User Impact & Adoption Potential | X2: Business Value | Z2: Implementation Effort
K3: High | L3: Major penalty/loss prevention and/or direct revenue/profit driver + time to value < 3 months | N3: Applicable across all business divisions with minimal customization | P3: Requires integration across multiple systems with different technologies (e.g., Salesforce + SAP + others), complex data orchestration needs | R3: Meets requirements: Use case can be implemented with ACP Level 2 or lower | T3: Complements existing initiatives, creates synergies | V3: Addresses Siemens pain point and a large user base that is employee-facing (e.g. Sales Reps) | X3: =L3 | Z3: Requires >6 months
K4: Medium | L4: Moderate efficiency gains and/or indirect contribution + time to value 3-6 months | N4: Widely applicable but requires some customization per business division | P4: Requires integration between 1-2 systems on similar technology (e.g., multiple Salesforce orgs), standard data requirements | R4: - | T4: No overlap, independent initiative | V4: Addresses Siemens pain point and a affects a smaller number of user or user base is customer-facing | X4: =L4 | Z4: Requires 3-6 months
K5: Low | L5: Minor savings and/or cost savings only + time to value > 6 months | N5: Limited to single business division or single use case | P5: Self-contained within one system (e.g., Salesforce), no external integrations required, aligns with existing AI standards | R5: Does not meet requirements: Requires ACP Level 3 or higher (potential blocker) | T5: Duplicates existing efforts or conflicts with current business roadmap(s) | V5: Does not address a Siemens pain point | X5: =L5 | Z5: Can be implemented in ≤3 months
F6: What system does the agent mostly operate in | G6: What are the input sources | H6: What does the agent do, from trigger to operating mode | I6: What is the agents output | J6: How can we determine the value of each agent | K6: ACN Agentfactory | L6: The agents should be able to provide quick wins and demonstrate measurable business impact, such as improved productivity, cost savings, or revenue generation. | N6: The agents should not be limited to a specific business division (e.g., DI or SI) but should be applicable across the organization. | P6: The agents should be feasible to implement within the existing technical constraints and align with Siemens' AI standards and orchestration capabilities (e.g. data cloud capabilities). | R6: The agents should not require level 3 as this would be an additional challenge (e.g. SieSales currently has ACP level 2 data). | T6: The agents should not duplicate efforts or overlap with the agent use cases already being worked on by the team. -> No overlap (no), yes there are similar use cases already worked on based on SI/DI/Agentforce use cases (yes) | V6: The agents should address the needs of a significant user base and target specific pain points or gaps in the current CRM usage. | X6: As before based on "cost avoidance", "sales & profitability" and "time to value (months)". -> see "Business Value Potential" | Z6: Based on implementation time.
A7: Master Data Quality Agent | B7: Duplicate Detection Sub-Agent | C7: Identifies and flags duplicate customer records across systems using fuzzy matching algorithms | D7: Data fragmentation across multiple CRM/ERP systems leading to duplicate customer records, inconsistent account hierarchies, and wasted sales effort on same prospects | E7: Salesforce Einstein, ML-based fuzzy matching, Probabilistic record linkage algorithms | F7: SAP MDG | G7: Customer records (SF CRM, MDG); Fuzzy matching rules; Historical duplicate patterns | H7: Triggered on new/changed customer records. Runs ML-based similarity algorithms to identify potential duplicates across name, address, tax ID. Scores matches and flags high-confidence duplicates for auto-merge or review. | I7: Duplicate alerts with confidence score; Merge recommendations; Auto-merge execution (>95% confidence) | J7: Duplicate detection rate; False positive rate; Auto-merge accuracy | L7: High, Medium or Low | M7: [Reasoning] | N7: High, Medium or Low | O7: [Reasoning] | P7: High, Medium or Low | Q7: [Reasoning] | R7: High or Low | S7: [Reasoning] | T7: High, Medium or Low | U7: [Reasoning] | V7: High, Medium or Low | W7: [Reasoning] | X7: =L7 | Y7: [Reasoning] | Z7: High, Medium or Low | AA7: [Reasoning]
A8: Master Data Quality Agent | B8: Address Validation Sub-Agent | F8: SAP MDG | G8: Address data from all sources; Postal database feeds; Geolocation services | H8: Triggered on address creation/update. Calls external address validation APIs, standardizes formats, verifies deliverability, enriches with geolocation data. Auto-corrects minor errors and flags major issues. | I8: Validated addresses; Correction suggestions; Validation status flags; Geocoordinates | J8: Validation success rate; Auto-correction rate; Delivery failure reduction | X8: =L8
A9: Master Data Quality Agent | B9: Data Completeness Sub-Agent | F9: SAP MDG | G9: Customer master records; Required field definitions by segment; Business rules repository | H9: Triggered on record save. Evaluates completeness based on customer segment, transaction type, and regulatory requirements. Calculates completeness scores and identifies missing critical data. | I9: Completeness score (0-100); Missing field alerts; Priority ranking; Enrichment recommendations | J9: Overall completeness score; Critical field completion rate; Time to complete records | X9: =L9
A10: Master Data Quality Agent | B10: Data Consistency Sub-Agent | F10: SAP MDG | G10: Multi-system customer data; Cross-reference rules; Hierarchy validations | H10: Triggered on sync events. Compares customer data across CRM, ERP, billing systems. Detects inconsistencies in account hierarchies, payment terms, credit limits. Applies resolution rules or escalates conflicts. | I10: Consistency violation reports; Auto-reconciliation actions; Conflict resolution recommendations | J10: Data consistency score; Cross-system sync errors; Reconciliation time | X10: =L10
A11: Master Data Quality Agent | B11: Data Change Monitoring Sub-Agent | F11: SAP MDG | G11: Change logs from all systems; Audit rules; Suspicious pattern definitions | H11: Continuously monitors data changes. Detects anomalous patterns (bulk changes, unauthorized modifications, rapid updates). Triggers alerts for suspicious activities and maintains audit trail. | I11: Change history reports; Anomaly alerts; Audit documentation; Rollback triggers | J11: Anomaly detection rate; Audit compliance score; Mean time to detect issues | X11: =L11
A12: Quote Configuration Agent | B12: Product Recommendation Sub-Agent | F12: SF RCA | G12: Customer requirements; Customer profile & history; Product catalog; Pricing rules | H12: Triggered when quote initiated. Analyzes customer needs, industry, size, purchase history. Runs recommendation engine to suggest products, bundles, and configurations. Considers margin optimization and inventory availability. | I12: Recommended products ranked by fit; Bundle suggestions; Alternative options; Justification rationale | J12: Recommendation acceptance rate; Upsell success rate; Quote value increase | K12: Automated opportunity and quote creation | X12: =L12
A13: Quote Configuration Agent | B13: Pricing Optimization Sub-Agent | F13: SF RCA | G13: Product selections; Pricing rules & matrices; Competitive intelligence; Customer agreements | H13: Triggered after product selection. Calculates optimal pricing considering volume discounts, contract terms, competitive positioning, margin targets. Suggests discount levels and validates against approval thresholds. | I13: Optimized pricing; Discount recommendations; Pricing rationale; Margin analysis; Approval requirements | J13: Win rate by pricing tier; Margin realization; Discount variance | K13: Intelligent product and discount recommendations | X13: =L13
A14: Quote Configuration Agent | B14: Technical Feasibility Sub-Agent | F14: SF RCA | G14: Product configurations; Technical compatibility rules; Engineering constraints; Customer environment data | H14: Triggered during configuration. Validates technical compatibility of selected products, checks for conflicts, verifies installation requirements. Flags engineering review needs for custom configurations. | I14: Feasibility assessment; Configuration warnings; Engineering escalation flags; Alternative configurations | J14: Configuration error rate; Engineering escalation rate; First-time-right quotes | X14: =L14
A15: Quote Configuration Agent | B15: Upsell/Cross-sell Opportunity Sub-Agent | F15: SF RCA | G15: Current quote items; Customer installed base; Product affinity rules; Campaign data | H15: Triggered during quote building. Identifies relevant add-ons, upgrades, complementary products based on what's in cart and customer history. Scores opportunities by likelihood and value. | I15: Ranked upsell opportunities; Cross-sell suggestions; Value messaging; Success probability scores | J15: Attach rate; Average deal size increase; Opportunity conversion rate | X15: =L15
A16: Quote Configuration Agent | B16: Quote Validation Sub-Agent | F16: SF RCA | G16: Complete quote data; Business rules; Approval policies; Historical won/lost data | H16: Triggered before quote submission. Performs comprehensive validation of pricing, discounts, configurations, terms. Checks completeness, compliance with policies. Determines required approval routing. | I16: Validation results; Error/warning list; Approval routing decision; Risk assessment | J16: Quote error rate; Rework percentage; Time to validate | X16: =L16
A17: Credit Decision Agent | B17: Credit Data Aggregation Sub-Agent | F17: SAP S/4HANA | G17: Credit bureau APIs (cFIN); Domain screening (EDS); Contact data (Contarget); Internal AR history | H17: Triggered on credit check request. Orchestrates parallel API calls to multiple credit bureaus and screening services. Consolidates responses, handles timeouts/errors, enriches with internal payment history data. | I17: Consolidated credit report; Bureau scores; Screening results; Payment history summary | J17: Data retrieval time; API success rate; Data completeness | X17: =L17
A18: Credit Decision Agent | B18: Risk Scoring Sub-Agent | F18: SAP S/4HANA | G18: Aggregated credit data; Corporate hierarchy; Industry benchmarks; Current exposure | H18: Triggered after data aggregation. Applies ML-based risk model incorporating bureau scores, payment patterns, industry risk, corporate structure. Calculates probability of default and expected loss. | I18: Risk score (0-1000); Risk category (A-E); Default probability; Contributing risk factors | J18: Model accuracy (vs. actual defaults); Score stability; Prediction power | X18: =L18
A19: Credit Decision Agent | B19: Credit Limit Calculation Sub-Agent | F19: SAP S/4HANA | G19: Risk score; Financial statements; Order value; Payment terms; Existing exposure | H19: Triggered after risk scoring. Calculates recommended credit limit using risk-based pricing models, considers requested amount, existing exposure, collateral. Optimizes for risk-adjusted return. | I19: Recommended credit limit; Limit justification; Required collateral/guarantees; Monitoring thresholds | J19: Limit utilization rate; Credit losses; Revenue at risk | X19: =L19
A20: Credit Decision Agent | B20: Approval Routing Sub-Agent | F20: SAP S/4HANA | G20: Risk assessment results; Credit limit recommendation; Approval policies; Organizational hierarchy | H20: Triggered after limit calculation. Determines approval requirements based on risk level, amount, policy exceptions. Routes to appropriate approvers, sets SLAs, manages escalations for overdue approvals. | I20: Approval workflow route; Required approver list; Justification package; SLA timers | J20: Auto-approval rate; Approval cycle time; Escalation rate | K20: Slack Agent routes notifications and approval requests directly to Slack for faster action | X20: =L20
A21: Credit Decision Agent | B21: Credit Monitoring Sub-Agent | F21: SAP S/4HANA | G21: Approved credit limits; Transaction activity; Credit bureau alerts; Payment performance | H21: Continuously monitors approved customers. Tracks credit utilization, payment timeliness, bureau score changes. Triggers alerts for deteriorating conditions, recommends limit adjustments or holds. | I21: Monitoring alerts; Limit adjustment recommendations; Payment hold triggers; Portfolio risk reports | J21: Early warning accuracy; Limit breach incidents; Loss prevention | X21: =L21
A22: Compliance Orchestration Agent | B22: Sanctions Screening Sub-Agent | F22: SAP GTS | G22: Customer data; Sanctions lists (OFAC, UN, EU, etc.); Product/service details; Destination country | H22: Triggered on customer creation and quote validation. Screens customer names, addresses, beneficial owners against multiple sanctions lists. Uses fuzzy matching with configurable thresholds to reduce false positives. | I22: Screening results (Pass/Fail/Review); Match details with scores; Recommended actions; Audit documentation | J22: Screening time; False positive rate; Match accuracy | X22: =L22
A23: Compliance Orchestration Agent | B23: Export Control Classification Sub-Agent | F23: SAP GTS | G23: Product details; Technical specifications; Export control databases (CCL, ECCN); Destination country | H23: Triggered when products added to quote. Automatically classifies products against export control lists, determines licensing requirements, checks destination country restrictions. Flags controlled items. | I23: Product classification codes; License requirements; Export restrictions; Documentation needs | J23: Classification accuracy; Licensing compliance rate; Classification time | X23: =L23
A24: Compliance Orchestration Agent | B24: Denied Party Screening Sub-Agent | F24: SAP GTS | G24: End-user details; Intermediaries; Denied party lists (BIS, State Dept); Transaction parties | H24: Triggered during quote validation. Screens all transaction parties (buyer, end-user, intermediaries, freight forwarders) against denied party lists. Validates ownership structures for shell company risks. | I24: Party screening results; Risk assessment by party; Beneficial owner analysis; Red flag alerts | J24: Screening coverage; Hit rate accuracy; Investigation time | X24: =L24
A25: Compliance Orchestration Agent | B25: End-Use Validation Sub-Agent | F25: SAP GTS | G25: Customer declarations; Product usage patterns; Industry analysis; Historical behavior | H25: Triggered for controlled products. Analyzes declared end-use against product capabilities, customer industry, and historical patterns. Detects potential misuse risks through anomaly detection. | I25: End-use assessment (Low/Medium/High risk); Anomaly alerts; Recommended restrictions; Due diligence requirements | J25: Risk detection accuracy; Diversion prevention rate; Assessment time | X25: =L25
A26: Compliance Orchestration Agent | B26: Compliance Documentation Sub-Agent | F26: SAP GTS | G26: All screening results; Regulatory requirements; License data; Approval decisions | H26: Triggered at quote approval. Consolidates all compliance checks, generates required documentation (licenses, declarations, certificates), ensures audit trail completeness, prepares export filing data. | I26: Compliance certificate; Export documentation package; Audit trail report; Filing-ready data | J26: Documentation completeness; Audit readiness score; Generation time | X26: =L26
A27: Quote Routing & Approval Agent | B27: Deal Characteristic Analysis Sub-Agent | F27: SF CRM | G27: Quote details; Customer data; Historical deal data; Organizational rules | H27: Triggered after credit and compliance checks pass. Analyzes deal size, complexity, discount levels, risk factors, strategic importance. Scores deal on multiple dimensions to determine routing needs. | I27: Deal complexity score; Risk assessment; Strategic value rating; Routing requirements | J27: Scoring accuracy; Analysis time; Routing appropriateness | X27: =L27
A28: Quote Routing & Approval Agent | B28: Approver Selection Sub-Agent | F28: SF CRM | G28: Deal characteristics; Approval policies; Organizational hierarchy (HRIS); Approver availability/workload | H28: Triggered after deal analysis. Determines required approvers based on policies (discount %, deal size, risk level). Considers approver availability, current workload, delegation rules. Optimizes for fastest approval. | I28: Approver list with sequence; Justification for each approver; Delegation assignments; Parallel vs. sequential routing | J28: Routing accuracy; Approval cycle time; Workload balance | X28: =L28
A29: Quote Routing & Approval Agent | B29: Approval Workflow Orchestration Sub-Agent | F29: SF CRM | G29: Approver selections; Deal justification package; SLA policies; Business calendar | H29: Triggered after approver selection. Creates workflow instances, sends notifications with context, tracks responses, manages parallel approvals, handles conditional routing based on responses, escalates overdue items. | I29: Workflow status updates; Notifications to approvers; Escalation triggers; Real-time tracking dashboard | J29: On-time approval rate; Escalation frequency; Workflow completion time | X29: =L29
A30: Quote Routing & Approval Agent | B30: Approval Decision Support Sub-Agent | F30: SF CRM | G30: Deal details; Business rules repository; Similar historical deals; Win/loss data | H30: Triggered when approver opens workflow. Provides decision support by showing comparable deals, win probability, risk factors, margin analysis. Highlights policy exceptions and suggests conditions. | I30: Decision recommendation; Comparable deal analysis; Risk/reward summary; Suggested conditions/terms | J30: Decision quality (vs. outcomes); Approver satisfaction; Information usefulness | X30: =L30
A31: Quote Routing & Approval Agent | B31: Workflow Exception Handling Sub-Agent | F31: SF CRM | G31: Workflow status; Approver responses; Rejection reasons; Policy override requests | H31: Continuously monitors workflows. Handles rejections by routing back to sales with feedback, manages policy override requests, deals with approver unavailability, executes fallback routing, logs all exceptions. | I31: Exception routing decisions; Feedback to sales team; Override approvals; Exception audit log | J31: Exception resolution time; Override approval rate; Rework cycles | X31: =L31
A32: Quote Conversion Agent | B32: Conversion Readiness Sub-Agent | F32: SF CRM | G32: Quote approval status; Lead time data; Customer PO status; Contract execution status | H32: Triggered when quote approved. Validates all prerequisites for conversion: customer acceptance received, purchase order obtained, contract signed, delivery dates confirmed. Calculates optimal conversion timing. | I32: Readiness assessment (Ready/Waiting/Blocked); Missing prerequisites list; Recommended conversion date; Risk flags | J32: Conversion success rate; Time from approval to conversion; Prerequisite completion rate | X32: =L32
... A38: Quote Conversion Agent | B38: Conversion Exception Resolution Sub-Agent | F38: SF CRM | G38: Conversion errors; Conflict details; Resolution rules; Historical resolution patterns | H38: Triggered on conversion failures. Analyzes error types, attempts auto-resolution for known issues, enriches missing data where possible. Routes complex exceptions to appropriate teams with context and recommendations. | I38: Resolution actions taken; Escalation tickets with context; Retry schedules; Resolution recommendations | J38: Auto-resolution rate; Mean time to resolution; Escalation accuracy | X38: =L38
A39: Sales Enablement Agent | B39: Account Intelligence Summary Sub-Agent | D39: N/A | E39: Salesforce Agentforce | F39: SF CRM | G39: Customer master data (SF CRM, SAP MDG); Opportunity and quote history (SF CRM); Order and delivery history (SAP S/4HANA); Payment history and credit status (SAP S/4HANA); Support tickets and product issues (Service Cloud); Customer communications (Email, Slack); Product usage data and adoption metrics; Stakeholder mapping and org chart data; Industry news and company announcements; Competitive win/loss intelligence | H39: Triggered on-demand by sales reps (pre-call, pre-meeting) or scheduled for regular account reviews. Aggregates data from multiple systems via APIs and creates a unified view of the customer relationship. Applies natural language processing to summarize recent interactions, support issues, and sentiment trends. Identifies key stakeholders, decision-makers, and relationship strength. Highlights account health indicators (revenue trends, product adoption, support satisfaction, payment behavior). Detects risks (churn signals, competitive threats, unresolved issues) and opportunities (upsell potential, contract renewal timing, expansion triggers). Generates executive summary in natural language tailored to the sales rep's upcoming activity (call prep, QBR, proposal development). Continuously learns from rep feedback on summary usefulness. | I39: Executive account summary (2-3 paragraphs); Account health score with trend indicators; Recent activity timeline (orders, issues, communications); Key stakeholder map with relationship strength; Risk alerts (churn signals, payment issues, satisfaction drops); Opportunity highlights (upsell potential, whitespace analysis); Recommended talking points and questions for next interaction; Competitive intelligence relevant to this account; Action items requiring follow-up | J39: Time saved on account research per sales rep per week; Meeting preparation time reduction; Sales rep satisfaction with account insights; Meeting effectiveness score (rep and customer feedback); Customer engagement quality improvement; Early risk detection rate (churn prevention); Upsell/cross-sell opportunity identification accuracy; Account retention rate improvement | X39: =L39
A40: Sales Enablement Agent | B40: Sales Communication Generation Sub-Agent | D40: N/A | E40: Salesforce Agentforce | F40: SF CRM | G40: Customer profile and communication history (SF CRM); Deal context (quote details, stage, concerns, competitors); Email templates and best practice library; Previous successful communication patterns (won deals); Customer sentiment and engagement preferences; Product information and value propositions; Industry-specific messaging guidelines; Regulatory and compliance requirements for communications; Sales rep writing style and preferences; Meeting notes and action items from recent interactions | H40: Triggered when sales rep initiates email composition for specific scenarios (quote follow-up, proposal submission, meeting request, objection handling, contract negotiation, status update). Analyzes the context: customer relationship stage, recent interactions, outstanding issues, deal characteristics, and communication objective. Generates personalized email content using large language models fine-tuned on successful sales communications. Adapts tone based on customer seniority, industry, relationship maturity, and cultural context. Incorporates relevant data points (quote details, pricing, delivery dates) automatically from CRM. Suggests optimal subject lines based on open rate data. Provides multiple variants with different approaches (consultative, urgent, value-focused). Ensures compliance with industry regulations and company policies. Learns from rep edits and email performance (opens, responses, conversions) to improve future generations. | I40: Personalized email draft with multiple variants; Optimized subject line suggestions with predicted open rates; Tone and style recommendations based on context; Suggested call-to-action and next steps; Attachment recommendations (proposals, case studies, ROI calculators); Optimal send time prediction; Compliance check results (regulatory, legal, brand); Follow-up reminder schedule; A/B testing suggestions for important communications | J40: Email composition time reduction per sales rep; Email open rate improvement; Email response rate improvement; Meeting acceptance rate (for meeting requests); Quote acceptance rate (for proposal emails); Communication consistency across sales team; Sales rep adoption rate of generated content; Customer satisfaction with sales communications; Conversion rate by communication type; Time saved on email writing per week (team-wide) | X40: =L40
A41: Sales Enablement Agent | B41: Deal Status Intelligence Sub-Agent | D41: N/A | E41: Salesforce Agentforce | F41: SF CRM | G41: Quote data and status (SF CPQ); Approval workflow status (SF CRM); SAP order data (SAP S/4HANA); Production and fulfillment status (SAP); Shipping and delivery tracking (Logistics systems); Payment and invoicing status (SAP FI); Customer acceptance and signatures (DocuSign, Adobe Sign); Support tickets related to the deal (Service Cloud); Customer engagement data (quote views, portal activity); Historical timeline of all deal activities | H41: Triggered on-demand when sales rep views an opportunity, quote, or order, or scheduled for proactive status updates. Orchestrates API calls to multiple systems (SF CPQ, SF CRM, SAP S/4HANA, logistics, payment) to gather current status from each stage of the quote-to-cash process. Applies business logic to determine overall deal health and progress. Creates a unified timeline view showing all activities, approvals, order creation, production milestones, shipping events, and payment status. Uses natural language generation to create executive summary of where the deal stands. Identifies bottlenecks, delays, or risks (e.g., stuck in approval, production delayed, payment overdue). Highlights required actions and next steps for the sales rep. Provides customer-facing status that can be shared externally. Maintains historical snapshots for trend analysis and predictive insights on deal velocity. | I41: Unified deal status dashboard with visual timeline; Executive summary in natural language (current status, next steps); Stage-by-stage progress tracker (Quote → Approval → Order → Production → Delivery → Payment); Blocker and risk alerts with recommended actions; Expected completion dates for each pending stage; Customer-facing status summary (shareable); Historical activity log with all events and changes; Proactive notifications when status changes or issues arise; Comparison to similar deals (velocity benchmarking) | J41: Time saved on status inquiries per sales rep per week; Reduction in 'Where is my order?' customer inquiries; Deal cycle time visibility and predictability improvement; Proactive issue identification rate (before customer complaint); Sales rep satisfaction with deal visibility; Customer satisfaction with transparency and communication; Reduction in deals lost due to poor communication or delays; Forecast accuracy improvement through better visibility | X41: =L41
A42: Revenue Cloud Agent | B42: Subscription Management Sub-Agent | D42: N/A | E42: Salesforce Agentforce | F42: SF Revenue Cloud | G42: Subscription data (SF Revenue Cloud); Customer usage and consumption data; Contract terms and renewal dates; Customer engagement and product adoption metrics; Pricing and discount rules; Customer health score (CSM data); Historical renewal and churn patterns; Competitive intelligence and market pricing; Customer support ticket trends; Payment history and credit status | H42: Triggered by subscription lifecycle events (approaching renewal, usage threshold breach, contract anniversary, customer-initiated change request) or runs scheduled jobs for proactive management. Monitors subscription health by analyzing usage patterns, engagement metrics, and support interactions. Predicts renewal likelihood using ML models trained on historical churn data. For renewals, generates optimized renewal quotes considering usage trends, market pricing, competitive positioning, and customer health. For upgrades/downgrades, validates requested changes against usage patterns and recommends optimal tier. Automates routine subscription modifications (seat additions, usage adjustments) within defined parameters. For at-risk renewals, triggers proactive outreach with retention offers. Manages subscription amendments by validating pricing, proration calculations, and contract term impacts. Handles subscription consolidation for customers with multiple contracts. Ensures revenue recognition alignment with subscription changes. | I42: Renewal recommendations with optimized pricing; Churn risk alerts with retention strategies; Upsell/downsell recommendations based on usage; Automated subscription modifications (within policy); Prorated pricing calculations for mid-term changes; Contract consolidation suggestions; Renewal forecast with probability scores; Customer engagement playbooks for renewals; Revenue impact analysis for subscription changes | J42: Subscription renewal rate improvement; Net revenue retention (NRR) increase; Churn rate reduction; Time to process subscription changes; Upsell conversion rate from usage-based recommendations; Customer lifetime value (CLV) improvement; Subscription management operational efficiency; Revenue leakage reduction (pricing errors, missed renewals) | X42: =L42
A43: Revenue Cloud Agent | B43: Revenue Recognition Sub-Agent | D43: N/A | E43: Salesforce Agentforce | F43: SF Revenue Cloud | G43: Contract terms and revenue schedules (SF Revenue Cloud); Order and fulfillment data (SAP S/4HANA); Service delivery milestones and acceptance; Accounting standards and policies (ASC 606, IFRS 15); Performance obligations and deliverables; Stand-alone selling prices (SSP); Contract modifications and amendments; Variable consideration and constraints; Multi-element arrangement rules; Revenue allocation policies | H43: Triggered when new orders are created, contracts are signed, or delivery milestones are achieved. Analyzes contract terms to identify distinct performance obligations (products, services, subscriptions). Determines transaction price including variable consideration, discounts, and financing components. Allocates transaction price to performance obligations based on stand-alone selling prices using waterfall or residual approaches. Applies revenue recognition rules based on performance obligation type (point in time vs. over time). Creates revenue schedules considering contract start dates, service periods, and delivery milestones. Handles complex scenarios: contract modifications, cancellations, refunds, and amendments. Adjusts revenue schedules dynamically as contracts change or obligations are fulfilled. Ensures compliance with ASC 606/IFRS 15 requirements including disclosure tracking. Integrates with general ledger to post revenue recognition entries automatically. Maintains audit trail of all recognition decisions and rule applications. Flags unusual scenarios or policy exceptions for accounting review. | I43: Revenue recognition schedules by performance obligation; Transaction price allocation breakdowns; Automated journal entries for revenue posting; Deferred revenue tracking and forecasts; Revenue waterfall reports (bookings to recognized revenue); Compliance validation reports (ASC 606/IFRS 15); Contract modification impact analysis; Exception alerts requiring accounting review; Revenue disclosure data for financial reporting | J43: Revenue recognition cycle time (order to recognition); Manual accounting interventions (reduction); Audit finding rate related to revenue recognition; Revenue forecast accuracy improvement; Deferred revenue accuracy and predictability; Month-end close time reduction; Compliance adherence rate (ASC 606/IFRS 15); Revenue restatement incidents (reduction) | X43: =L43
A44: Revenue Cloud Agent | B44: Contract Amendment Sub-Agent | D44: N/A | E44: Salesforce Agentforce | F44: SF Revenue Cloud | G44: Original contract terms (SF Revenue Cloud); Amendment request details (scope, pricing, timing); Current revenue recognition schedules; Historical amendment patterns and approvals; Pricing and discount policies; Customer relationship and contract history; Legal and compliance requirements; Approval authority matrix; Revenue impact modeling rules; Contract change risk factors | H44: Triggered when customer or sales rep initiates contract change request (add products, change quantities, adjust pricing, extend/reduce term, modify service levels). Validates amendment request against contract terms, identifying restrictions or penalties. Calculates financial impact including proration, credit adjustments, new pricing, and term extensions. Determines whether amendment is treated as contract modification (cumulative catch-up) or new contract under revenue recognition rules. Recalculates revenue schedules considering remaining performance obligations and new transaction price. Evaluates amendment against business policies (discount thresholds, approval requirements, margin targets). Generates amendment quote with all pricing, credits, and term adjustments pre-filled. Routes for appropriate approvals based on financial impact and policy exceptions. Creates amendment documentation with clear explanation of changes and customer impact. Updates all related systems (billing, revenue recognition, order management) upon approval. Maintains version control and audit trail of all contract changes. Flags risky amendments (significant revenue reduction, unusual terms) for additional review. | I44: Amendment impact analysis (financial, revenue recognition, legal); Automated amendment quote with all adjustments; Proration and credit calculations; Updated revenue recognition schedules; Approval routing with justification package; Amendment documentation (customer-facing and internal); Risk assessment and compliance validation; System update coordination across platforms; Version-controlled contract history | J44: Amendment processing time (reduction); Amendment error rate (pricing, proration, revenue impact); Customer satisfaction with amendment process; Revenue leakage from amendment errors (reduction); Amendment approval cycle time; Self-service amendment success rate; Contract compliance with amendment policies; Amendment-related revenue restatements (reduction) | X44: =L44
A45: Experience Cloud Agent | B45: Customer Portal Self-Service Sub-Agent | D45: N/A | E45: Salesforce Agentforce | F45: SF Experience Cloud | G45: Customer account data (SF CRM); Order and delivery status (SAP S/4HANA); Product catalog and pricing (SF CPQ); Support case history (Service Cloud); Knowledge base and documentation; Invoice and payment data (SAP FI); User behavior and portal analytics; Customer preferences and permissions; Contract and entitlement data; Customer intent signals and query patterns | H45: Operates within customer-facing Experience Cloud portal, triggered by customer actions or queries. Acts as intelligent virtual assistant understanding customer intent through natural language processing. For order status inquiries, retrieves real-time data from multiple systems and presents unified timeline with shipment tracking. For document requests (invoices, quotes, contracts, certificates), identifies correct documents, verifies customer entitlement, and provides secure download links. For reorder requests, analyzes purchase history, checks current pricing and availability, and generates quote automatically. For simple support inquiries, searches knowledge base and provides relevant articles with contextual recommendations. For complex issues, intelligently routes to appropriate support team with full context. Enables self-service subscription management (view usage, upgrade/downgrade within limits, update billing info). Provides personalized product recommendations based on purchase history and usage patterns. Learns from successful vs. unsuccessful self-service interactions to improve deflection rates. Escalates to human agent when confidence is low or customer explicitly requests, providing full interaction context. | I45: Conversational responses to customer queries (chat/voice); Real-time order and delivery status with tracking; Automated document retrieval and download; Self-service quote generation for reorders; Contextual knowledge article recommendations; Subscription management interface (usage, billing, upgrades); Intelligent case creation and routing (when needed); Personalized product and service recommendations; Proactive notifications (order shipped, payment due, renewal approaching) | J45: Customer self-service deflection rate; Support case volume reduction; Customer satisfaction with portal experience (CSAT, NPS); Average time to resolution for self-service inquiries; Portal adoption rate and engagement metrics; Self-service transaction completion rate; Cost per customer interaction (reduction); Reorder conversion rate through portal | X45: =L45
...

Sheet Agents Siemens crit - review
H1: Agent Specification | N1: Siemens Criteria | Z1: Value x Effort
N2: Business Value Potential | P2: Cross-business Applicability | R2: Technical Complexity & Feasibility | T2: Data readiness and ACP compliance | V2: Alignment with existing initiatives | X2: User Impact & Adoption Potential | Z2: Business Value | AB2: Implementation Effort
N3: Major penalty/loss prevention and/or direct revenue/profit driver + time to value < 3 months | P3: Applicable across all business divisions with minimal customization | R3: Requires integration across multiple systems with different technologies (e.g., Salesforce + SAP + others), complex data orchestration needs | T3: Meets requirements: Use case can be implemented with ACP Level 2 or lower | V3: Complements existing initiatives, creates synergies | X3: Addresses Siemens pain point and a large user base that is employee-facing (e.g. Sales Reps) | Z3: =N3 | AB3: Requires >6 months
N4: Moderate efficiency gains and/or indirect contribution + time to value 3-6 months | P4: Widely applicable but requires some customization per business division | R4: Requires integration between 1-2 systems on similar technology (e.g., multiple Salesforce orgs), standard data requirements | T4: - | V4: No overlap, independent initiative | X4: Addresses Siemens pain point and a affects a smaller number of user or user base is customer-facing | Z4: =N4 | AB4: Requires 3-6 months
H5: Host System | I5: Input (Sources/Supplier) | J5: How does this agent technically work? | K5: Agent Output | L5: KPIs to measure business impact | M5: ACN Asset | N5: Minor savings and/or cost savings only + time to value > 6 months | P5: Limited to single business division or single use case | R5: Self-contained within one system (e.g., Salesforce), no external integrations required, aligns with existing AI standards | T5: Does not meet requirements: Requires ACP Level 3 or higher (potential blocker) | V5: Duplicates existing efforts or conflicts with current business roadmap(s) | X5: Does not address a Siemens pain point | Z5: =N5 | AB5: Can be implemented in ≤3 months
A6: Super Agent Use Case | B6: Sub-Agent Use Cases | C6: Agent Description (short) | D6: Pain Point Addressed | E6: Agent Practicality and Tech. (Does this qualify to be AI Agent use case? If yes, what is the agent tech?) | F6: Rationale for column E | G6: Used Technology | H6: What system does the agent mostly operate in | I6: What are the input sources | J6: What does the agent do, from trigger to operating mode | K6: What is the agents output | L6: How can we determine the value of each agent | N6: The agents should be able to provide quick wins and demonstrate measurable business impact, such as improved productivity, cost savings, or revenue generation. | P6: The agents should not be limited to a specific business division (e.g., DI or SI) but should be applicable across the organization. | R6: The agents should be feasible to implement within the existing technical constraints and align with Siemens' AI standards and orchestration capabilities (e.g. data cloud capabilities). | T6: The agents should not require level 3 as this would be an additional challenge (e.g. SieSales currently has ACP level 2 data). | V6: The agents should not duplicate efforts or overlap with the agent use cases already being worked on by the team. -> No overlap (no), yes there are similar use cases already worked on based on SI/DI/Agentforce use cases (yes) | X6: The agents should address the needs of a significant user base and target specific pain points or gaps in the current CRM usage. | Z6: As before based on "cost avoidance", "sales & profitability" and "time to value (months)". -> see "Business Value Potential" | AB6: Based on implementation time.
A7: Master Data Quality Agent | B7: Duplicate Detection Sub-Agent | C7: Detects when the same corporate account (company) exists multiple times in CRM/ERP by comparing company names, tax IDs, DUNS numbers, and registered addresses using similarity scoring (e.g., 'Siemens AG' vs 'Siemens A.G.' scores 95% match). Flags duplicates for merge or manual review. | D7: [Data Fragmentation & Siloed Information] Same corporate account exists 3-5 times across CRM/ERP systems with different spellings (e.g., 'BMW AG', 'BMW Group', 'Bayerische Motoren Werke'). Sales reps unknowingly compete on same account. Credit limits fragmented. Account history incomplete. | E7: Does not qualify as AI Agent | F7: RATIONALE: TECHNOLOGY: OOB: SAP MDG Duplicate Check, Salesforce Data Cloud Matching Rules | CUSTOM: MuleSoft cross-system sync EVIDENCE FROM HOST SYSTEM (SAP MDG): - SAP MDG has built-in OOB duplicate detection - Primary system is ERP, not Salesforce-native EVIDENCE FROM INPUT SOURCES: - Structured data with predefined fuzzy matching rules - No learned patterns, no ML training data specified CONCLUSION: Core functionality (fuzzy matching, similarity scoring 0-100%, auto-merge >95%, cross-system sync) is achievable with OOB tools. AI designation requires adding genuine ML (e.g., learning from data steward merge/reject decisions). | G7: OOB: SAP MDG Duplicate Check, Salesforce Data Cloud Matching Rules | CUSTOM: MuleSoft integration for cross-system deduplication workflow (sync duplicates flagged in either system) | H7: SAP MDG + Salesforce Data Cloud (OOB). MuleSoft cross-system sync (CUSTOM). | I7: Corporate account records (Salesforce CRM, SAP MDG); Company name variations; Tax IDs (VAT, DUNS); Registered addresses; Account hierarchies | J7: Triggered on new/changed corporate account records in either Salesforce or SAP MDG. SAP MDG Duplicate Check and Salesforce Data Cloud Matching Rules run similarity algorithms on company name, tax ID, address. Scores matches (0-100%). High-confidence duplicates (>95%) auto-merged; others queued for data steward review. | K7: Duplicate alerts with confidence score; Merge recommendations; Auto-merge execution (>95%); Cross-system duplicate notification via MuleSoft | L7: Duplicate record reduction rate; False positive rate (<5% target); Auto-merge accuracy; Sales rep time saved (hours/week) | N7: Low | O7: Limited direct revenue impact. Primarily operational efficiency. Consider bundling with related agents to increase value proposition. | P7: High | Q7: Master data quality affects all divisions using shared CRM/ERP systems. Duplicate accounts, address errors, and data inconsistencies impact DI, SI, and MO equally. | R7: Medium | S7: 2 system integrations required. Systems: SAP MDG, Salesforce Data Cloud, MuleSoft. Some custom development needed. Standard connectors and APIs available. | T7: High | U7: Standard CRM data. ACP Level 2 sufficient for implementation. | V7: Medium | W7: RELATED SAP SOLUTION: SAP Master Data Consistency (F18) - AVAILABLE in SAP Joule catalog, NOT DEPLOYED at Siemens. (SOURCE: SAP Joule Feature List - external, requires Siemens IT verification). SAP F18 function: Checks data consistency within S/4HANA MDG. SPECIFIC DIFFERENTIATOR: Duplicate Detection operates in SALESFORCE (Account/Contact dedup), not S/4HANA MDG. Different data sources (SFDC vs SAP), different matching algorithms. Checked: AF (12), DI (10), SI (9) - NONE address Salesforce-specific deduplication. | X7: Medium | Y7: Addresses [Data Fragmentation & Siloed Information] pain point. 'Same corporate account exists 3-5 times across CRM/ERP systems with different spellings (e...'. Moderate user impact. | Z7: Low | AA7: Limited direct revenue impact. Primarily operational efficiency. Consider bundling with related agents to increase value proposition. | AB7: High | AC7: Extended timeline: >6 months. Complex factors: SAP integration, custom development. Plan for phased rollout.
